Workbook

Sheet Summary
A1: C1 – Week 2 · Team 4 · Summary of results
A2: All values below are linked to the detailed sheets. Validation sets: QSD1 (30 cropped queries) · QSD2 (GT crop) = QSD2 paintings cropped with the GT mask · BG_Removal (T5) = QSD2 cropped with OUR masks (the real Task 5 pipeline). Only method1 is submitted (the week-2 instructions ask for one method).
A4: Method | B4: Descriptor | C4: map@1 QSD1 | D4: map@5 QSD1 | E4: map@1 QSD2 (GT crop) | F4: map@5 QSD2 (GT crop) | G4: map@1 + BG_Removal (T5) | H4: map@5 + BG_Removal (T5)
A5: W1 method 1 | B5: HSV 1D, 16 bins, Chi-square (global) | C5: ='1. Global 1D-2D-3D'!F50 -> 0.9 | D5: ='1. Global 1D-2D-3D'!G50 -> 0.95 | E5: ='1. Global 1D-2D-3D'!H50 -> 0.56666667 | F5: ='1. Global 1D-2D-3D'!I50 -> 0.63833333 | G5: ='1. Global 1D-2D-3D'!J50 -> 0.5 | H5: ='1. Global 1D-2D-3D'!K50 -> 0.57777778
A6: W1 method 2 | B6: Lab 1D, 32 bins, Hellinger (global) | C6: ='1. Global 1D-2D-3D'!F119 -> 0.9 | D6: ='1. Global 1D-2D-3D'!G119 -> 0.92222222 | E6: ='1. Global 1D-2D-3D'!H119 -> 0.7 | F6: ='1. Global 1D-2D-3D'!I119 -> 0.75388889 | G6: ='1. Global 1D-2D-3D'!J119 -> 0.53333333 | H6: ='1. Global 1D-2D-3D'!K119 -> 0.62222222
A7: W2 method1 (submitted) | B7: YCrCb 3D 6×12×12 range-adapted bins, pyramid 1×1+2×2+4×4+8×8 (weights 1:2:4:8), Hellinger, 5% margin | C7: ='6. Margin + BG removal (T5)'!D89 -> 0.96666667 | D7: ='6. Margin + BG removal (T5)'!E89 -> 0.96666667 | E7: ='6. Margin + BG removal (T5)'!F89 -> 1 | F7: ='6. Margin + BG removal (T5)'!G89 -> 1 | G7: ='6. Margin + BG removal (T5)'!H89 -> 0.96666667 | H7: ='6. Margin + BG removal (T5)'!I89 -> 0.98333333
A8: W2 method2 (comparison) | B8: HSV 3D 8×6×6 uniform bins, 5×5 blocks, Hellinger, 5% margin | C8: ='6. Margin + BG removal (T5)'!D29 -> 0.96666667 | D8: ='6. Margin + BG removal (T5)'!E29 -> 0.96666667 | E8: ='6. Margin + BG removal (T5)'!F29 -> 1 | F8: ='6. Margin + BG removal (T5)'!G29 -> 1 | G8: ='6. Margin + BG removal (T5)'!H29 -> 0.93333333 | H8: ='6. Margin + BG removal (T5)'!I29 -> 0.96111111
A10: Background removal (QSD2, method M2) | C10: Precision | D10: Recall | E10: F1
A11: Gaussian model of the wall colour (Lab, robust border statistics) + Mahalanobis + Otsu + morphology | C11: ='7. BG removal (T3-T4)'!D7 -> 0.9534996 | D11: ='7. BG removal (T3-T4)'!E7 -> 0.96602679 | E11: ='7. BG removal (T3-T4)'!F7 -> 0.9559358
A13: Values for the common slide tables | C13: Value
A14: Task 2: map@1 QSD1-W1 (best previous week) | C14: =MAX(C5:C6) -> 0.9
A15: Task 2: map@1 QSD1-W2 (best this week) | C15: =C7 -> 0.96666667
A16: Task 4: Precision | C16: =C11 -> 0.9534996
A17: Task 4: Recall | C17: =D11 -> 0.96602679
A18: Task 4: F1 | C18: =E11 -> 0.9559358
A19: Task 5: map@1 QSD2-W2 | C19: =G7 -> 0.96666667
A21: Sheets
A22: 1. Global 1D-2D-3D | B22: Histogram type × colour space × bins × similarity, whole image (Task 1)
A23: 2. Bin placement | B23: uniform vs range-adapted vs quantile bins, and different bins per channel (Task 1)
A24: 3. Block based | B24: number of blocks × bins (Task 1)
A25: 4. Spatial pyramid | B25: pyramid levels and level weights (Task 1)
A26: 5. Distances | B26: similarity measures on the best descriptors
A27: 6. Margin + BG removal (T5) | B27: inner margin vs retrieval with our masks; final methods (Task 5)
A28: 7. BG removal (T3-T4) | B28: background models, ablation, extra variants and per-image P/R/F1 (Tasks 3–4)
A29: 8. Discarded (normalisation) | B29: limiting the gain of the illumination normalisation (discarded)
A31: Green cells in the detailed sheets = best value of that column. Mean columns are formulas (AVERAGE) of the columns to their left.

Sheet 1. Global 1D-2D-3D
A1: Global histograms (1×1): 1D vs 2D vs 3D, colour space, bins and similarity (uniform bins)
A2: Notebook §3.2. Illumination normalisation (mean 128 per RGB channel) before every histogram. Green = best value of the column.
A3: Color space | B3: Histogram | C3: Bins per channel | D3: Descriptor dim. | E3: Similarity | F3: map@1 QSD1 | G3: map@5 QSD1 | H3: map@1 QSD2 (GT crop) | I3: map@5 QSD2 (GT crop) | J3: map@1 + BG_Removal (T5) | K3: map@5 + BG_Removal (T5) | L3: MRR QSD1 | M3: MRR QSD2 (GT crop) | N3: MRR + BG_Removal (T5) | O3: Mean map@1 (QSD1 + QSD2-GT) | P3: Mean map@1 (3 sets) | Q3: Mean MRR (3 sets)
A4: RGB | B4: 1D (per channel) | C4: 8 | D4: 24 | E4: Jensen-Shannon | F4: 0.7 | G4: 0.78888889 | H4: 0.6 | I4: 0.64166667 | J4: 0.4 | K4: 0.49555556 | L4: 0.79631851 | M4: 0.6551584 | N4: 0.52283131 | O4: =AVERAGE(F4,H4) -> 0.65 | P4: =AVERAGE(F4,H4,J4) -> 0.56666667 | Q4: =AVERAGE(L4,M4,N4) -> 0.65810274
E5: L1 (= intersection) | F5: 0.63333333 | G5: 0.75388889 | H5: 0.53333333 | I5: 0.60833333 | J5: 0.4 | K5: 0.49 | L5: 0.75525132 | M5: 0.61915524 | N5: 0.50818601 | O5: =AVERAGE(F5,H5) -> 0.58333333 | P5: =AVERAGE(F5,H5,J5) -> 0.52222222 | Q5: =AVERAGE(L5,M5,N5) -> 0.62753086
E6: Chi-square | F6: 0.7 | G6: 0.78888889 | H6: 0.6 | I6: 0.64166667 | J6: 0.4 | K6: 0.49555556 | L6: 0.79628831 | M6: 0.65502172 | N6: 0.52127448 | O6: =AVERAGE(F6,H6) -> 0.65 | P6: =AVERAGE(F6,H6,J6) -> 0.56666667 | Q6: =AVERAGE(L6,M6,N6) -> 0.65752817
E7: Hellinger | F7: 0.7 | G7: 0.78888889 | H7: 0.6 | I7: 0.64166667 | J7: 0.4 | K7: 0.50222222 | L7: 0.79634414 | M7: 0.65499347 | N7: 0.52162151 | O7: =AVERAGE(F7,H7) -> 0.65 | P7: =AVERAGE(F7,H7,J7) -> 0.56666667 | Q7: =AVERAGE(L7,M7,N7) -> 0.65765304
C8: 16 | D8: 48 | E8: Jensen-Shannon | F8: 0.73333333 | G8: 0.82222222 | H8: 0.6 | I8: 0.65 | J8: 0.5 | K8: 0.55944444 | L8: 0.82442907 | M8: 0.6635792 | N8: 0.57976488 | O8: =AVERAGE(F8,H8) -> 0.66666667 | P8: =AVERAGE(F8,H8,J8) -> 0.61111111 | Q8: =AVERAGE(L8,M8,N8) -> 0.68925772
E9: L1 (= intersection) | F9: 0.66666667 | G9: 0.75277778 | H9: 0.6 | I9: 0.64277778 | J9: 0.43333333 | K9: 0.52222222 | L9: 0.76559524 | M9: 0.65356246 | N9: 0.54129891 | O9: =AVERAGE(F9,H9) -> 0.63333333 | P9: =AVERAGE(F9,H9,J9) -> 0.56666667 | Q9: =AVERAGE(L9,M9,N9) -> 0.65348554
E10: Chi-square | F10: 0.73333333 | G10: 0.82222222 | H10: 0.6 | I10: 0.65 | J10: 0.46666667 | K10: 0.54277778 | L10: 0.82436869 | M10: 0.66355062 | N10: 0.56357773 | O10: =AVERAGE(F10,H10) -> 0.66666667 | P10: =AVERAGE(F10,H10,J10) -> 0.6 | Q10: =AVERAGE(L10,M10,N10) -> 0.68383234
E11: Hellinger | F11: 0.7 | G11: 0.80277778 | H11: 0.6 | I11: 0.65 | J11: 0.5 | K11: 0.55944444 | L11: 0.80505051 | M11: 0.66443845 | N11: 0.57994021 | O11: =AVERAGE(F11,H11) -> 0.65 | P11: =AVERAGE(F11,H11,J11) -> 0.6 | Q11: =AVERAGE(L11,M11,N11) -> 0.68314305
C12: 32 | D12: 96 | E12: Jensen-Shannon | F12: 0.7 | G12: 0.78888889 | H12: 0.56666667 | I12: 0.62888889 | J12: 0.46666667 | K12: 0.54444444 | L12: 0.79111326 | M12: 0.64298187 | N12: 0.56475964 | O12: =AVERAGE(F12,H12) -> 0.63333333 | P12: =AVERAGE(F12,H12,J12) -> 0.57777778 | Q12: =AVERAGE(L12,M12,N12) -> 0.66628492
E13: L1 (= intersection) | F13: 0.66666667 | G13: 0.74555556 | H13: 0.6 | I13: 0.63444444 | J13: 0.43333333 | K13: 0.50833333 | L13: 0.75695915 | M13: 0.65088859 | N13: 0.53352245 | O13: =AVERAGE(F13,H13) -> 0.63333333 | P13: =AVERAGE(F13,H13,J13) -> 0.56666667 | Q13: =AVERAGE(L13,M13,N13) -> 0.6471234
E14: Chi-square | F14: 0.76666667 | G14: 0.82055556 | H14: 0.6 | I14: 0.64555556 | J14: 0.5 | K14: 0.56111111 | L14: 0.82269928 | M14: 0.65941154 | N14: 0.58106934 | O14: =AVERAGE(F14,H14) -> 0.68333333 | P14: =AVERAGE(F14,H14,J14) -> 0.62222222 | Q14: =AVERAGE(L14,M14,N14) -> 0.68772672
E15: Hellinger | F15: 0.66666667 | G15: 0.77222222 | H15: 0.56666667 | I15: 0.62333333 | J15: 0.43333333 | K15: 0.52222222 | L15: 0.77461353 | M15: 0.63741362 | N15: 0.5421812 | O15: =AVERAGE(F15,H15) -> 0.61666667 | P15: =AVERAGE(F15,H15,J15) -> 0.55555556 | Q15: =AVERAGE(L15,M15,N15) -> 0.65140278
C16: 64 | D16: 192 | E16: Jensen-Shannon | F16: 0.73333333 | G16: 0.78833333 | H16: 0.53333333 | I16: 0.59722222 | J16: 0.43333333 | K16: 0.51388889 | L16: 0.79276984 | M16: 0.61212588 | N16: 0.53513937 | O16: =AVERAGE(F16,H16) -> 0.63333333 | P16: =AVERAGE(F16,H16,J16) -> 0.56666667 | Q16: =AVERAGE(L16,M16,N16) -> 0.64667836
E17: L1 (= intersection) | F17: 0.7 | G17: 0.75277778 | H17: 0.6 | I17: 0.61944444 | J17: 0.4 | K17: 0.465 | L17: 0.76901739 | M17: 0.64167453 | N17: 0.4937139 | O17: =AVERAGE(F17,H17) -> 0.65 | P17: =AVERAGE(F17,H17,J17) -> 0.56666667 | Q17: =AVERAGE(L17,M17,N17) -> 0.63480194
E18: Chi-square | F18: 0.73333333 | G18: 0.78166667 | H18: 0.53333333 | I18: 0.59555556 | J18: 0.5 | K18: 0.54444444 | L18: 0.79205556 | M18: 0.61063582 | N18: 0.56612727 | O18: =AVERAGE(F18,H18) -> 0.63333333 | P18: =AVERAGE(F18,H18,J18) -> 0.58888889 | Q18: =AVERAGE(L18,M18,N18) -> 0.65627288
E19: Hellinger | F19: 0.7 | G19: 0.77333333 | H19: 0.53333333 | I19: 0.59166667 | J19: 0.43333333 | K19: 0.50833333 | L19: 0.77775098 | M19: 0.60655968 | N19: 0.52982878 | O19: =AVERAGE(F19,H19) -> 0.61666667 | P19: =AVERAGE(F19,H19,J19) -> 0.55555556 | Q19: =AVERAGE(L19,M19,N19) -> 0.63804648
B20: 3D (joint) | C20: 4 | D20: 64 | E20: Jensen-Shannon | F20: 0.9 | G20: 0.92777778 | H20: 0.7 | I20: 0.74555556 | J20: 0.5 | K20: 0.595 | L20: 0.93333333 | M20: 0.75674473 | N20: 0.6108196 | O20: =AVERAGE(F20,H20) -> 0.8 | P20: =AVERAGE(F20,H20,J20) -> 0.7 | Q20: =AVERAGE(L20,M20,N20) -> 0.76696589
E21: L1 (= intersection) | F21: 0.8 | G21: 0.82777778 | H21: 0.63333333 | I21: 0.68611111 | J21: 0.4 | K21: 0.49555556 | L21: 0.83991172 | M21: 0.69917166 | N21: 0.52104027 | O21: =AVERAGE(F21,H21) -> 0.71666667 | P21: =AVERAGE(F21,H21,J21) -> 0.61111111 | Q21: =AVERAGE(L21,M21,N21) -> 0.68670789
E22: Chi-square | F22: 0.9 | G22: 0.92333333 | H22: 0.7 | I22: 0.73888889 | J22: 0.5 | K22: 0.58166667 | L22: 0.92809524 | M22: 0.75326782 | N22: 0.60959219 | O22: =AVERAGE(F22,H22) -> 0.8 | P22: =AVERAGE(F22,H22,J22) -> 0.7 | Q22: =AVERAGE(L22,M22,N22) -> 0.76365175
E23: Hellinger | F23: 0.9 | G23: 0.93444444 | H23: 0.7 | I23: 0.74722222 | J23: 0.53333333 | K23: 0.615 | L23: 0.93444444 | M23: 0.75898872 | N23: 0.63055083 | O23: =AVERAGE(F23,H23) -> 0.8 | P23: =AVERAGE(F23,H23,J23) -> 0.71111111 | Q23: =AVERAGE(L23,M23,N23) -> 0.77466133
C24: 6 | D24: 216 | E24: Jensen-Shannon | F24: 0.96666667 | G24: 0.98333333 | H24: 0.76666667 | I24: 0.80111111 | J24: 0.66666667 | K24: 0.73888889 | L24: 0.98333333 | M24: 0.81424339 | N24: 0.75003242 | O24: =AVERAGE(F24,H24) -> 0.86666667 | P24: =AVERAGE(F24,H24,J24) -> 0.8 | Q24: =AVERAGE(L24,M24,N24) -> 0.84920305
E25: L1 (= intersection) | F25: 0.9 | G25: 0.95 | H25: 0.73333333 | I25: 0.76666667 | J25: 0.6 | K25: 0.70111111 | L25: 0.95 | M25: 0.78257937 | N25: 0.70853571 | O25: =AVERAGE(F25,H25) -> 0.81666667 | P25: =AVERAGE(F25,H25,J25) -> 0.74444444 | Q25: =AVERAGE(L25,M25,N25) -> 0.81370503
E26: Chi-square | F26: 0.96666667 | G26: 0.98333333 | H26: 0.76666667 | I26: 0.79444444 | J26: 0.66666667 | K26: 0.74111111 | L26: 0.98333333 | M26: 0.8110582 | N26: 0.74815376 | O26: =AVERAGE(F26,H26) -> 0.86666667 | P26: =AVERAGE(F26,H26,J26) -> 0.8 | Q26: =AVERAGE(L26,M26,N26) -> 0.8475151
E27: Hellinger | F27: 0.9 | G27: 0.95 | H27: 0.8 | I27: 0.82444444 | J27: 0.7 | K27: 0.75555556 | L27: 0.95 | M27: 0.83271605 | N27: 0.76494359 | O27: =AVERAGE(F27,H27) -> 0.85 | P27: =AVERAGE(F27,H27,J27) -> 0.8 | Q27: =AVERAGE(L27,M27,N27) -> 0.84921988
C28: 8 | D28: 512 | E28: Jensen-Shannon | F28: 1 | G28: 1 | H28: 0.8 | I28: 0.84 | J28: 0.73333333 | K28: 0.765 | L28: 1 | M28: 0.85066919 | N28: 0.7746176 | O28: =AVERAGE(F28,H28) -> 0.9 | P28: =AVERAGE(F28,H28,J28) -> 0.84444444 | Q28: =AVERAGE(L28,M28,N28) -> 0.8750956
E29: L1 (= intersection) | F29: 0.9 | G29: 0.94444444 | H29: 0.73333333 | I29: 0.76111111 | J29: 0.56666667 | K29: 0.66111111 | L29: 0.94444444 | M29: 0.78193957 | N29: 0.67768756 | O29: =AVERAGE(F29,H29) -> 0.81666667 | P29: =AVERAGE(F29,H29,J29) -> 0.73333333 | Q29: =AVERAGE(L29,M29,N29) -> 0.80135719
E30: Chi-square | F30: 1 | G30: 1 | H30: 0.8 | I30: 0.83444444 | J30: 0.73333333 | K30: 0.75833333 | L30: 1 | M30: 0.84512821 | N30: 0.77158554 | O30: =AVERAGE(F30,H30) -> 0.9 | P30: =AVERAGE(F30,H30,J30) -> 0.84444444 | Q30: =AVERAGE(L30,M30,N30) -> 0.87223792
E31: Hellinger | F31: 1 | G31: 1 | H31: 0.8 | I31: 0.85 | J31: 0.76666667 | K31: 0.78333333 | L31: 1 | M31: 0.86054664 | N31: 0.7926977 | O31: =AVERAGE(F31,H31) -> 0.9 | P31: =AVERAGE(F31,H31,J31) -> 0.85555556 | Q31: =AVERAGE(L31,M31,N31) -> 0.88441478
C32: 12 | D32: 1728 | E32: Jensen-Shannon | F32: 1 | G32: 1 | H32: 0.76666667 | I32: 0.83444444 | J32: 0.76666667 | K32: 0.79444444 | L32: 1 | M32: 0.84333333 | N32: 0.80598813 | O32: =AVERAGE(F32,H32) -> 0.88333333 | P32: =AVERAGE(F32,H32,J32) -> 0.84444444 | Q32: =AVERAGE(L32,M32,N32) -> 0.88310716
E33: L1 (= intersection) | F33: 0.9 | G33: 0.93611111 | H33: 0.76666667 | I33: 0.81777778 | J33: 0.73333333 | K33: 0.76666667 | L33: 0.93611111 | M33: 0.82784512 | N33: 0.77933815 | O33: =AVERAGE(F33,H33) -> 0.83333333 | P33: =AVERAGE(F33,H33,J33) -> 0.8 | Q33: =AVERAGE(L33,M33,N33) -> 0.84776479
E34: Chi-square | F34: 0.96666667 | G34: 0.98333333 | H34: 0.76666667 | I34: 0.82222222 | J34: 0.76666667 | K34: 0.79444444 | L34: 0.98333333 | M34: 0.83703704 | N34: 0.80529101 | O34: =AVERAGE(F34,H34) -> 0.86666667 | P34: =AVERAGE(F34,H34,J34) -> 0.83333333 | Q34: =AVERAGE(L34,M34,N34) -> 0.87522046
E35: Hellinger | F35: 1 | G35: 1 | H35: 0.76666667 | I35: 0.83888889 | J35: 0.76666667 | K35: 0.8 | L35: 1 | M35: 0.8468254 | N35: 0.81208596 | O35: =AVERAGE(F35,H35) -> 0.88333333 | P35: =AVERAGE(F35,H35,J35) -> 0.84444444 | Q35: =AVERAGE(L35,M35,N35) -> 0.88630379
C36: 16 | D36: 4096 | E36: Jensen-Shannon | F36: 1 | G36: 1 | H36: 0.83333333 | I36: 0.89444444 | J36: 0.76666667 | K36: 0.80777778 | L36: 1 | M36: 0.9 | N36: 0.8119434 | O36: =AVERAGE(F36,H36) -> 0.91666667 | P36: =AVERAGE(F36,H36,J36) -> 0.86666667 | Q36: =AVERAGE(L36,M36,N36) -> 0.90398113
E37: L1 (= intersection) | F37: 1 | G37: 1 | H37: 0.76666667 | I37: 0.84944444 | J37: 0.6 | K37: 0.7 | L37: 1 | M37: 0.84944444 | N37: 0.71750397 | O37: =AVERAGE(F37,H37) -> 0.88333333 | P37: =AVERAGE(F37,H37,J37) -> 0.78888889 | Q37: =AVERAGE(L37,M37,N37) -> 0.85564947
E38: Chi-square | F38: 1 | G38: 1 | H38: 0.83333333 | I38: 0.88333333 | J38: 0.73333333 | K38: 0.78444444 | L38: 1 | M38: 0.88888889 | N38: 0.7943864 | O38: =AVERAGE(F38,H38) -> 0.91666667 | P38: =AVERAGE(F38,H38,J38) -> 0.85555556 | Q38: =AVERAGE(L38,M38,N38) -> 0.8944251
E39: Hellinger | F39: 1 | G39: 1 | H39: 0.8 | I39: 0.875 | J39: 0.76666667 | K39: 0.80555556 | L39: 1 | M39: 0.87916667 | N39: 0.81428042 | O39: =AVERAGE(F39,H39) -> 0.9 | P39: =AVERAGE(F39,H39,J39) -> 0.85555556 | Q39: =AVERAGE(L39,M39,N39) -> 0.8978157
C40: 24 | D40: 13824 | E40: Jensen-Shannon | F40: 0.96666667 | G40: 0.97777778 | H40: 0.76666667 | I40: 0.85 | J40: 0.73333333 | K40: 0.79166667 | L40: 0.97777778 | M40: 0.85858586 | N40: 0.79664717 | O40: =AVERAGE(F40,H40) -> 0.86666667 | P40: =AVERAGE(F40,H40,J40) -> 0.82222222 | Q40: =AVERAGE(L40,M40,N40) -> 0.87767027
...

Sheet 2. Bin placement
A1: Where to place the bins: uniform over [0,255] vs range-adapted vs quantile (global 3D histograms)
A2: Notebook §3.3. uniform = equal width over the full channel range; range-adapted = equal width over the 0.5–99.5 percentile of the BBDD pixels; quantile = each bin gets the same number of BBDD pixels.
A3: Color space | B3: Bins per channel | C3: Bin placement | D3: Similarity | E3: map@1 QSD1 | F3: map@5 QSD1 | G3: map@1 QSD2 (GT crop) | H3: map@5 QSD2 (GT crop) | I3: map@1 + BG_Removal (T5) | J3: map@5 + BG_Removal (T5) | K3: MRR QSD1 | L3: MRR QSD2 (GT crop) | M3: MRR + BG_Removal (T5) | N3: Mean map@1 (QSD1 + QSD2-GT) | O3: Mean map@1 (3 sets) | P3: Mean MRR (3 sets)
A4: RGB | B4: 8 (8×8×8) | C4: uniform | D4: Chi-square | E4: 1 | F4: 1 | G4: 0.8 | H4: 0.83444444 | I4: 0.73333333 | J4: 0.75833333 | K4: 1 | L4: 0.84512821 | M4: 0.77158554 | N4: =AVERAGE(E4,G4) -> 0.9 | O4: =AVERAGE(E4,G4,I4) -> 0.84444444 | P4: =AVERAGE(K4,L4,M4) -> 0.87223792
D5: Hellinger | E5: 1 | F5: 1 | G5: 0.8 | H5: 0.85 | I5: 0.76666667 | J5: 0.78333333 | K5: 1 | L5: 0.86054664 | M5: 0.7926977 | N5: =AVERAGE(E5,G5) -> 0.9 | O5: =AVERAGE(E5,G5,I5) -> 0.85555556 | P5: =AVERAGE(K5,L5,M5) -> 0.88441478
C6: range-adapted | D6: Chi-square | E6: 1 | F6: 1 | G6: 0.8 | H6: 0.82888889 | I6: 0.73333333 | J6: 0.775 | K6: 1 | L6: 0.8403848 | M6: 0.78728349 | N6: =AVERAGE(E6,G6) -> 0.9 | O6: =AVERAGE(E6,G6,I6) -> 0.84444444 | P6: =AVERAGE(K6,L6,M6) -> 0.87588943
D7: Hellinger | E7: 1 | F7: 1 | G7: 0.8 | H7: 0.84166667 | I7: 0.76666667 | J7: 0.79166667 | K7: 1 | L7: 0.84665775 | M7: 0.80235591 | N7: =AVERAGE(E7,G7) -> 0.9 | O7: =AVERAGE(E7,G7,I7) -> 0.85555556 | P7: =AVERAGE(K7,L7,M7) -> 0.88300456
C8: quantile | D8: Chi-square | E8: 0.96666667 | F8: 0.98333333 | G8: 0.76666667 | H8: 0.81666667 | I8: 0.8 | J8: 0.81666667 | K8: 0.98333333 | L8: 0.8348545 | M8: 0.8304792 | N8: =AVERAGE(E8,G8) -> 0.86666667 | O8: =AVERAGE(E8,G8,I8) -> 0.84444444 | P8: =AVERAGE(K8,L8,M8) -> 0.88288901
D9: Hellinger | E9: 1 | F9: 1 | G9: 0.8 | H9: 0.84166667 | I9: 0.8 | J9: 0.81666667 | K9: 1 | L9: 0.85535714 | M9: 0.83026474 | N9: =AVERAGE(E9,G9) -> 0.9 | O9: =AVERAGE(E9,G9,I9) -> 0.86666667 | P9: =AVERAGE(K9,L9,M9) -> 0.89520729
B10: 12 (12×12×12) | C10: uniform | D10: Chi-square | E10: 0.96666667 | F10: 0.98333333 | G10: 0.76666667 | H10: 0.82222222 | I10: 0.76666667 | J10: 0.79444444 | K10: 0.98333333 | L10: 0.83703704 | M10: 0.80529101 | N10: =AVERAGE(E10,G10) -> 0.86666667 | O10: =AVERAGE(E10,G10,I10) -> 0.83333333 | P10: =AVERAGE(K10,L10,M10) -> 0.87522046
D11: Hellinger | E11: 1 | F11: 1 | G11: 0.76666667 | H11: 0.83888889 | I11: 0.76666667 | J11: 0.8 | K11: 1 | L11: 0.8468254 | M11: 0.81208596 | N11: =AVERAGE(E11,G11) -> 0.88333333 | O11: =AVERAGE(E11,G11,I11) -> 0.84444444 | P11: =AVERAGE(K11,L11,M11) -> 0.88630379
C12: range-adapted | D12: Chi-square | E12: 1 | F12: 1 | G12: 0.76666667 | H12: 0.82888889 | I12: 0.76666667 | J12: 0.8 | K12: 1 | L12: 0.83259259 | M12: 0.81170697 | N12: =AVERAGE(E12,G12) -> 0.88333333 | O12: =AVERAGE(E12,G12,I12) -> 0.84444444 | P12: =AVERAGE(K12,L12,M12) -> 0.88143319
D13: Hellinger | E13: 1 | F13: 1 | G13: 0.76666667 | H13: 0.83888889 | I13: 0.76666667 | J13: 0.80666667 | K13: 1 | L13: 0.84722222 | M13: 0.81375902 | N13: =AVERAGE(E13,G13) -> 0.88333333 | O13: =AVERAGE(E13,G13,I13) -> 0.84444444 | P13: =AVERAGE(K13,L13,M13) -> 0.88699375
C14: quantile | D14: Chi-square | E14: 1 | F14: 1 | G14: 0.76666667 | H14: 0.83333333 | I14: 0.66666667 | J14: 0.74166667 | K14: 1 | L14: 0.84305556 | M14: 0.75529894 | N14: =AVERAGE(E14,G14) -> 0.88333333 | O14: =AVERAGE(E14,G14,I14) -> 0.81111111 | P14: =AVERAGE(K14,L14,M14) -> 0.86611816
D15: Hellinger | E15: 1 | F15: 1 | G15: 0.8 | H15: 0.86666667 | I15: 0.73333333 | J15: 0.775 | K15: 1 | L15: 0.87083333 | M15: 0.78873043 | N15: =AVERAGE(E15,G15) -> 0.9 | O15: =AVERAGE(E15,G15,I15) -> 0.84444444 | P15: =AVERAGE(K15,L15,M15) -> 0.88652125
A16: HSV | B16: 8 (8×8×8) | C16: uniform | D16: Chi-square | E16: 0.96666667 | F16: 0.975 | G16: 0.8 | H16: 0.86111111 | I16: 0.6 | J16: 0.70777778 | K16: 0.975 | L16: 0.86349206 | M16: 0.71189103 | N16: =AVERAGE(E16,G16) -> 0.88333333 | O16: =AVERAGE(E16,G16,I16) -> 0.78888889 | P16: =AVERAGE(K16,L16,M16) -> 0.8501277
D17: Hellinger | E17: 0.96666667 | F17: 0.975 | G17: 0.76666667 | H17: 0.84111111 | I17: 0.6 | J17: 0.70888889 | K17: 0.975 | L17: 0.84319444 | M17: 0.71335317 | N17: =AVERAGE(E17,G17) -> 0.86666667 | O17: =AVERAGE(E17,G17,I17) -> 0.77777778 | P17: =AVERAGE(K17,L17,M17) -> 0.84384921
C18: range-adapted | D18: Chi-square | E18: 0.96666667 | F18: 0.975 | G18: 0.8 | H18: 0.85833333 | I18: 0.63333333 | J18: 0.72444444 | K18: 0.975 | L18: 0.86018519 | M18: 0.72794369 | N18: =AVERAGE(E18,G18) -> 0.88333333 | O18: =AVERAGE(E18,G18,I18) -> 0.8 | P18: =AVERAGE(K18,L18,M18) -> 0.85437629
D19: Hellinger | E19: 0.93333333 | F19: 0.95833333 | G19: 0.76666667 | H19: 0.84555556 | I19: 0.6 | J19: 0.69722222 | K19: 0.95833333 | L19: 0.84740741 | M19: 0.71104975 | N19: =AVERAGE(E19,G19) -> 0.85 | O19: =AVERAGE(E19,G19,I19) -> 0.76666667 | P19: =AVERAGE(K19,L19,M19) -> 0.83893017
C20: quantile | D20: Chi-square | E20: 0.96666667 | F20: 0.96666667 | G20: 0.8 | H20: 0.85277778 | I20: 0.66666667 | J20: 0.75388889 | K20: 0.97142857 | L20: 0.86064815 | M20: 0.75962963 | N20: =AVERAGE(E20,G20) -> 0.88333333 | O20: =AVERAGE(E20,G20,I20) -> 0.81111111 | P20: =AVERAGE(K20,L20,M20) -> 0.86390212
D21: Hellinger | E21: 0.96666667 | F21: 0.96666667 | G21: 0.8 | H21: 0.86111111 | I21: 0.63333333 | J21: 0.74111111 | K21: 0.97083333 | L21: 0.86703704 | M21: 0.74620825 | N21: =AVERAGE(E21,G21) -> 0.88333333 | O21: =AVERAGE(E21,G21,I21) -> 0.8 | P21: =AVERAGE(K21,L21,M21) -> 0.86135954
B22: 16×8×8 | C22: uniform | D22: Chi-square | E22: 0.96666667 | F22: 0.975 | G22: 0.8 | H22: 0.85944444 | I22: 0.6 | J22: 0.71388889 | K22: 0.975 | L22: 0.86140523 | M22: 0.71735043 | N22: =AVERAGE(E22,G22) -> 0.88333333 | O22: =AVERAGE(E22,G22,I22) -> 0.78888889 | P22: =AVERAGE(K22,L22,M22) -> 0.85125189
D23: Hellinger | E23: 0.96666667 | F23: 0.97777778 | G23: 0.8 | H23: 0.85833333 | I23: 0.63333333 | J23: 0.73 | K23: 0.97777778 | L23: 0.86018519 | M23: 0.73373094 | N23: =AVERAGE(E23,G23) -> 0.88333333 | O23: =AVERAGE(E23,G23,I23) -> 0.8 | P23: =AVERAGE(K23,L23,M23) -> 0.8572313
C24: range-adapted | D24: Chi-square | E24: 0.96666667 | F24: 0.975 | G24: 0.8 | H24: 0.86222222 | I24: 0.63333333 | J24: 0.73055556 | K24: 0.975 | L24: 0.86407407 | M24: 0.7335928 | N24: =AVERAGE(E24,G24) -> 0.88333333 | O24: =AVERAGE(E24,G24,I24) -> 0.8 | P24: =AVERAGE(K24,L24,M24) -> 0.85755562
D25: Hellinger | E25: 0.93333333 | F25: 0.95833333 | G25: 0.8 | H25: 0.85277778 | I25: 0.63333333 | J25: 0.73722222 | K25: 0.95833333 | L25: 0.85814815 | M25: 0.74042288 | N25: =AVERAGE(E25,G25) -> 0.86666667 | O25: =AVERAGE(E25,G25,I25) -> 0.78888889 | P25: =AVERAGE(K25,L25,M25) -> 0.85230145
C26: quantile | D26: Chi-square | E26: 0.93333333 | F26: 0.95 | G26: 0.8 | H26: 0.85277778 | I26: 0.63333333 | J26: 0.74277778 | K26: 0.9547619 | L26: 0.85868911 | M26: 0.74553612 | N26: =AVERAGE(E26,G26) -> 0.86666667 | O26: =AVERAGE(E26,G26,I26) -> 0.78888889 | P26: =AVERAGE(K26,L26,M26) -> 0.85299571
D27: Hellinger | E27: 0.93333333 | F27: 0.95 | G27: 0.83333333 | H27: 0.87777778 | I27: 0.66666667 | J27: 0.765 | K27: 0.9530303 | L27: 0.88212121 | M27: 0.76798725 | N27: =AVERAGE(E27,G27) -> 0.88333333 | O27: =AVERAGE(E27,G27,I27) -> 0.81111111 | P27: =AVERAGE(K27,L27,M27) -> 0.86771292
A28: Lab | B28: 8 (8×8×8) | C28: uniform | D28: Chi-square | E28: 0.83333333 | F28: 0.89833333 | G28: 0.6 | H28: 0.70611111 | I28: 0.5 | J28: 0.62 | K28: 0.89833333 | L28: 0.71259259 | M28: 0.63327031 | N28: =AVERAGE(E28,G28) -> 0.71666667 | O28: =AVERAGE(E28,G28,I28) -> 0.64444444 | P28: =AVERAGE(K28,L28,M28) -> 0.74806541
D29: Hellinger | E29: 0.83333333 | F29: 0.91111111 | G29: 0.63333333 | H29: 0.73 | I29: 0.56666667 | J29: 0.63055556 | K29: 0.91111111 | L29: 0.74203704 | M29: 0.65884165 | N29: =AVERAGE(E29,G29) -> 0.73333333 | O29: =AVERAGE(E29,G29,I29) -> 0.67777778 | P29: =AVERAGE(K29,L29,M29) -> 0.77066327
C30: range-adapted | D30: Chi-square | E30: 0.93333333 | F30: 0.96111111 | G30: 0.8 | H30: 0.84944444 | I30: 0.76666667 | J30: 0.80555556 | K30: 0.96111111 | L30: 0.855 | M30: 0.81964141 | N30: =AVERAGE(E30,G30) -> 0.86666667 | O30: =AVERAGE(E30,G30,I30) -> 0.83333333 | P30: =AVERAGE(K30,L30,M30) -> 0.87858418
D31: Hellinger | E31: 0.96666667 | F31: 0.97777778 | G31: 0.8 | H31: 0.83611111 | I31: 0.76666667 | J31: 0.79722222 | K31: 0.97777778 | L31: 0.85277778 | M31: 0.81019962 | N31: =AVERAGE(E31,G31) -> 0.88333333 | O31: =AVERAGE(E31,G31,I31) -> 0.84444444 | P31: =AVERAGE(K31,L31,M31) -> 0.88025172
C32: quantile | D32: Chi-square | E32: 0.96666667 | F32: 0.96666667 | G32: 0.8 | H32: 0.85777778 | I32: 0.6 | J32: 0.715 | K32: 0.97142857 | L32: 0.85901235 | M32: 0.72536172 | N32: =AVERAGE(E32,G32) -> 0.88333333 | O32: =AVERAGE(E32,G32,I32) -> 0.78888889 | P32: =AVERAGE(K32,L32,M32) -> 0.85193421
D33: Hellinger | E33: 0.93333333 | F33: 0.95 | G33: 0.8 | H33: 0.86777778 | I33: 0.63333333 | J33: 0.72611111 | K33: 0.95555556 | L33: 0.86905983 | M33: 0.73578373 | N33: =AVERAGE(E33,G33) -> 0.86666667 | O33: =AVERAGE(E33,G33,I33) -> 0.78888889 | P33: =AVERAGE(K33,L33,M33) -> 0.85346637
B34: 8×16×16 | C34: uniform | D34: Chi-square | E34: 0.9 | F34: 0.93611111 | G34: 0.7 | H34: 0.79277778 | I34: 0.7 | J34: 0.76777778 | K34: 0.93611111 | L34: 0.79462963 | M34: 0.77861258 | N34: =AVERAGE(E34,G34) -> 0.8 | O34: =AVERAGE(E34,G34,I34) -> 0.76666667 | P34: =AVERAGE(K34,L34,M34) -> 0.83645111
D35: Hellinger | E35: 0.9 | F35: 0.94444444 | G35: 0.7 | H35: 0.79722222 | I35: 0.66666667 | J35: 0.74555556 | K35: 0.94444444 | L35: 0.80429293 | M35: 0.75791667 | N35: =AVERAGE(E35,G35) -> 0.8 | O35: =AVERAGE(E35,G35,I35) -> 0.75555556 | P35: =AVERAGE(K35,L35,M35) -> 0.83555135
C36: range-adapted | D36: Chi-square | E36: 0.93333333 | F36: 0.96666667 | G36: 0.8 | H36: 0.86777778 | I36: 0.66666667 | J36: 0.75111111 | K36: 0.96666667 | L36: 0.86777778 | M36: 0.76366995 | N36: =AVERAGE(E36,G36) -> 0.86666667 | O36: =AVERAGE(E36,G36,I36) -> 0.8 | P36: =AVERAGE(K36,L36,M36) -> 0.86603813
D37: Hellinger | E37: 0.93333333 | F37: 0.95277778 | G37: 0.83333333 | H37: 0.87777778 | I37: 0.73333333 | J37: 0.80277778 | K37: 0.95277778 | L37: 0.88194444 | M37: 0.80972718 | N37: =AVERAGE(E37,G37) -> 0.88333333 | O37: =AVERAGE(E37,G37,I37) -> 0.83333333 | P37: =AVERAGE(K37,L37,M37) -> 0.88148313
C38: quantile | D38: Chi-square | E38: 0.96666667 | F38: 0.96666667 | G38: 0.66666667 | H38: 0.79166667 | I38: 0.56666667 | J38: 0.68444444 | K38: 0.96944444 | L38: 0.7986715 | M38: 0.7006567 | N38: =AVERAGE(E38,G38) -> 0.81666667 | O38: =AVERAGE(E38,G38,I38) -> 0.73333333 | P38: =AVERAGE(K38,L38,M38) -> 0.82292421
D39: Hellinger | E39: 0.96666667 | F39: 0.96666667 | G39: 0.7 | H39: 0.81666667 | I39: 0.6 | J39: 0.69833333 | K39: 0.97 | L39: 0.82388889 | M39: 0.71469697 | N39: =AVERAGE(E39,G39) -> 0.83333333 | O39: =AVERAGE(E39,G39,I39) -> 0.75555556 | P39: =AVERAGE(K39,L39,M39) -> 0.83619529
A40: YCrCb | B40: 8 (8×8×8) | C40: uniform | D40: Chi-square | E40: 0.86666667 | F40: 0.92333333 | G40: 0.8 | H40: 0.82777778 | I40: 0.56666667 | J40: 0.65111111 | K40: 0.92333333 | L40: 0.84191919 | M40: 0.66918293 | N40: =AVERAGE(E40,G40) -> 0.83333333 | O40: =AVERAGE(E40,G40,I40) -> 0.74444444 | P40: =AVERAGE(K40,L40,M40) -> 0.81147849
...

Sheet 3. Block based
A1: Block based histograms (3D): number of blocks × bins
A2: Notebook §3.4. Non-overlapping n×n blocks, one normalised 3D histogram per block, concatenated. No inner margin (the margin is studied in sheet 6).
A3: Color space | B3: Bin placement | C3: Bins per channel | D3: Grid | E3: Number of blocks | F3: Descriptor dim. | G3: Similarity | H3: map@1 QSD1 | I3: map@5 QSD1 | J3: map@1 QSD2 (GT crop) | K3: map@5 QSD2 (GT crop) | L3: map@1 + BG_Removal (T5) | M3: map@5 + BG_Removal (T5) | N3: MRR QSD1 | O3: MRR QSD2 (GT crop) | P3: MRR + BG_Removal (T5) | Q3: Mean map@1 (QSD1 + QSD2-GT) | R3: Mean map@1 (3 sets) | S3: Mean MRR (3 sets)
A4: HSV | B4: uniform | C4: 4 (4×4×4) | D4: 1×1 | E4: 1 | F4: 64 | G4: Chi-square | H4: 0.9 | I4: 0.94 | J4: 0.56666667 | K4: 0.70833333 | L4: 0.53333333 | M4: 0.61666667 | N4: 0.94 | O4: 0.71920635 | P4: 0.63240207 | Q4: =AVERAGE(H4,J4) -> 0.73333333 | R4: =AVERAGE(H4,J4,L4) -> 0.66666667 | S4: =AVERAGE(N4,O4,P4) -> 0.76386947
G5: Hellinger | H5: 0.9 | I5: 0.925 | J5: 0.63333333 | K5: 0.73333333 | L5: 0.5 | M5: 0.59833333 | N5: 0.92916667 | O5: 0.74219577 | P5: 0.6163723 | Q5: =AVERAGE(H5,J5) -> 0.76666667 | R5: =AVERAGE(H5,J5,L5) -> 0.67777778 | S5: =AVERAGE(N5,O5,P5) -> 0.76257825
D6: 2×2 | E6: 4 | F6: 256 | G6: Chi-square | H6: 0.93333333 | I6: 0.96111111 | J6: 0.93333333 | K6: 0.95666667 | L6: 0.66666667 | M6: 0.73888889 | N6: 0.96111111 | O6: 0.95666667 | P6: 0.7587149 | Q6: =AVERAGE(H6,J6) -> 0.93333333 | R6: =AVERAGE(H6,J6,L6) -> 0.84444444 | S6: =AVERAGE(N6,O6,P6) -> 0.89216422
G7: Hellinger | H7: 0.93333333 | I7: 0.96666667 | J7: 0.9 | K7: 0.94166667 | L7: 0.7 | M7: 0.77055556 | N7: 0.96666667 | O7: 0.94166667 | P7: 0.7818254 | Q7: =AVERAGE(H7,J7) -> 0.91666667 | R7: =AVERAGE(H7,J7,L7) -> 0.84444444 | S7: =AVERAGE(N7,O7,P7) -> 0.89671958
D8: 3×3 | E8: 9 | F8: 576 | G8: Chi-square | H8: 0.96666667 | I8: 0.975 | J8: 0.96666667 | K8: 0.975 | L8: 0.73333333 | M8: 0.79833333 | N8: 0.975 | O8: 0.975 | P8: 0.81025253 | Q8: =AVERAGE(H8,J8) -> 0.96666667 | R8: =AVERAGE(H8,J8,L8) -> 0.88888889 | S8: =AVERAGE(N8,O8,P8) -> 0.92008418
G9: Hellinger | H9: 0.96666667 | I9: 0.975 | J9: 0.96666667 | K9: 0.975 | L9: 0.73333333 | M9: 0.79833333 | N9: 0.975 | O9: 0.975 | P9: 0.81138889 | Q9: =AVERAGE(H9,J9) -> 0.96666667 | R9: =AVERAGE(H9,J9,L9) -> 0.88888889 | S9: =AVERAGE(N9,O9,P9) -> 0.92046296
D10: 4×4 | E10: 16 | F10: 1024 | G10: Chi-square | H10: 0.96666667 | I10: 0.97777778 | J10: 0.96666667 | K10: 0.98333333 | L10: 0.76666667 | M10: 0.83444444 | N10: 0.97777778 | O10: 0.98333333 | P10: 0.84277778 | Q10: =AVERAGE(H10,J10) -> 0.96666667 | R10: =AVERAGE(H10,J10,L10) -> 0.9 | S10: =AVERAGE(N10,O10,P10) -> 0.93462963
G11: Hellinger | H11: 0.96666667 | I11: 0.97777778 | J11: 0.96666667 | K11: 0.98333333 | L11: 0.8 | M11: 0.85777778 | N11: 0.97777778 | O11: 0.98333333 | P11: 0.86111111 | Q11: =AVERAGE(H11,J11) -> 0.96666667 | R11: =AVERAGE(H11,J11,L11) -> 0.91111111 | S11: =AVERAGE(N11,O11,P11) -> 0.94074074
D12: 5×5 | E12: 25 | F12: 1600 | G12: Chi-square | H12: 0.96666667 | I12: 0.975 | J12: 1 | K12: 1 | L12: 0.86666667 | M12: 0.88444444 | N12: 0.975 | O12: 1 | P12: 0.89396825 | Q12: =AVERAGE(H12,J12) -> 0.98333333 | R12: =AVERAGE(H12,J12,L12) -> 0.94444444 | S12: =AVERAGE(N12,O12,P12) -> 0.95632275
G13: Hellinger | H13: 0.96666667 | I13: 0.97333333 | J13: 1 | K13: 1 | L13: 0.83333333 | M13: 0.87888889 | N13: 0.97333333 | O13: 1 | P13: 0.88259259 | Q13: =AVERAGE(H13,J13) -> 0.98333333 | R13: =AVERAGE(H13,J13,L13) -> 0.93333333 | S13: =AVERAGE(N13,O13,P13) -> 0.95197531
D14: 6×6 | E14: 36 | F14: 2304 | G14: Chi-square | H14: 0.96666667 | I14: 0.96666667 | J14: 1 | K14: 1 | L14: 0.9 | M14: 0.90833333 | N14: 0.97222222 | O14: 1 | P14: 0.9172619 | Q14: =AVERAGE(H14,J14) -> 0.98333333 | R14: =AVERAGE(H14,J14,L14) -> 0.95555556 | S14: =AVERAGE(N14,O14,P14) -> 0.96316138
G15: Hellinger | H15: 0.96666667 | I15: 0.96666667 | J15: 1 | K15: 1 | L15: 0.9 | M15: 0.91333333 | N15: 0.97222222 | O15: 1 | P15: 0.9175 | Q15: =AVERAGE(H15,J15) -> 0.98333333 | R15: =AVERAGE(H15,J15,L15) -> 0.95555556 | S15: =AVERAGE(N15,O15,P15) -> 0.96324074
D16: 8×8 | E16: 64 | F16: 4096 | G16: Chi-square | H16: 0.96666667 | I16: 0.96666667 | J16: 1 | K16: 1 | L16: 0.9 | M16: 0.91666667 | N16: 0.97083333 | O16: 1 | P16: 0.92222222 | Q16: =AVERAGE(H16,J16) -> 0.98333333 | R16: =AVERAGE(H16,J16,L16) -> 0.95555556 | S16: =AVERAGE(N16,O16,P16) -> 0.96435185
G17: Hellinger | H17: 0.96666667 | I17: 0.96666667 | J17: 1 | K17: 1 | L17: 0.9 | M17: 0.91944444 | N17: 0.97083333 | O17: 1 | P17: 0.92361111 | Q17: =AVERAGE(H17,J17) -> 0.98333333 | R17: =AVERAGE(H17,J17,L17) -> 0.95555556 | S17: =AVERAGE(N17,O17,P17) -> 0.96481481
C18: 8×6×6 | D18: 1×1 | E18: 1 | F18: 288 | G18: Chi-square | H18: 1 | I18: 1 | J18: 0.73333333 | K18: 0.82055556 | L18: 0.63333333 | M18: 0.71944444 | N18: 1 | O18: 0.82263889 | P18: 0.73233746 | Q18: =AVERAGE(H18,J18) -> 0.86666667 | R18: =AVERAGE(H18,J18,L18) -> 0.78888889 | S18: =AVERAGE(N18,O18,P18) -> 0.85165878
G19: Hellinger | H19: 0.96666667 | I19: 0.98333333 | J19: 0.76666667 | K19: 0.84 | L19: 0.63333333 | M19: 0.71666667 | N19: 0.98333333 | O19: 0.84185185 | P19: 0.73637978 | Q19: =AVERAGE(H19,J19) -> 0.86666667 | R19: =AVERAGE(H19,J19,L19) -> 0.78888889 | S19: =AVERAGE(N19,O19,P19) -> 0.85385499
D20: 2×2 | E20: 4 | F20: 1152 | G20: Chi-square | H20: 0.96666667 | I20: 0.975 | J20: 0.9 | K20: 0.94444444 | L20: 0.76666667 | M20: 0.83611111 | N20: 0.975 | O20: 0.94444444 | P20: 0.84212963 | Q20: =AVERAGE(H20,J20) -> 0.93333333 | R20: =AVERAGE(H20,J20,L20) -> 0.87777778 | S20: =AVERAGE(N20,O20,P20) -> 0.92052469
G21: Hellinger | H21: 0.96666667 | I21: 0.975 | J21: 0.9 | K21: 0.94166667 | L21: 0.8 | M21: 0.85 | N21: 0.975 | O21: 0.94166667 | P21: 0.85488215 | Q21: =AVERAGE(H21,J21) -> 0.93333333 | R21: =AVERAGE(H21,J21,L21) -> 0.88888889 | S21: =AVERAGE(N21,O21,P21) -> 0.92384961
D22: 3×3 | E22: 9 | F22: 2592 | G22: Chi-square | H22: 0.96666667 | I22: 0.975 | J22: 0.96666667 | K22: 0.96666667 | L22: 0.8 | M22: 0.85 | N22: 0.975 | O22: 0.96969697 | P22: 0.86001984 | Q22: =AVERAGE(H22,J22) -> 0.96666667 | R22: =AVERAGE(H22,J22,L22) -> 0.91111111 | S22: =AVERAGE(N22,O22,P22) -> 0.9349056
G23: Hellinger | H23: 0.96666667 | I23: 0.97333333 | J23: 0.96666667 | K23: 0.96666667 | L23: 0.83333333 | M23: 0.86666667 | N23: 0.97333333 | O23: 0.97037037 | P23: 0.87596478 | Q23: =AVERAGE(H23,J23) -> 0.96666667 | R23: =AVERAGE(H23,J23,L23) -> 0.92222222 | S23: =AVERAGE(N23,O23,P23) -> 0.93988949
D24: 4×4 | E24: 16 | F24: 4608 | G24: Chi-square | H24: 0.96666667 | I24: 0.975 | J24: 0.96666667 | K24: 0.98333333 | L24: 0.83333333 | M24: 0.88333333 | N24: 0.975 | O24: 0.98333333 | P24: 0.88809524 | Q24: =AVERAGE(H24,J24) -> 0.96666667 | R24: =AVERAGE(H24,J24,L24) -> 0.92222222 | S24: =AVERAGE(N24,O24,P24) -> 0.94880952
G25: Hellinger | H25: 0.96666667 | I25: 0.96666667 | J25: 0.96666667 | K25: 0.97777778 | L25: 0.83333333 | M25: 0.88166667 | N25: 0.97222222 | O25: 0.97777778 | P25: 0.88642857 | Q25: =AVERAGE(H25,J25) -> 0.96666667 | R25: =AVERAGE(H25,J25,L25) -> 0.92222222 | S25: =AVERAGE(N25,O25,P25) -> 0.94547619
D26: 5×5 | E26: 25 | F26: 7200 | G26: Chi-square | H26: 0.96666667 | I26: 0.96666667 | J26: 1 | K26: 1 | L26: 0.86666667 | M26: 0.90666667 | N26: 0.97222222 | O26: 1 | P26: 0.91222222 | Q26: =AVERAGE(H26,J26) -> 0.98333333 | R26: =AVERAGE(H26,J26,L26) -> 0.94444444 | S26: =AVERAGE(N26,O26,P26) -> 0.96148148
G27: Hellinger | H27: 0.96666667 | I27: 0.96666667 | J27: 0.96666667 | K27: 0.97777778 | L27: 0.93333333 | M27: 0.94166667 | N27: 0.97083333 | O27: 0.97777778 | P27: 0.94642857 | Q27: =AVERAGE(H27,J27) -> 0.96666667 | R27: =AVERAGE(H27,J27,L27) -> 0.95555556 | S27: =AVERAGE(N27,O27,P27) -> 0.96501323
D28: 6×6 | E28: 36 | F28: 10368 | G28: Chi-square | H28: 0.96666667 | I28: 0.96666667 | J28: 1 | K28: 1 | L28: 0.9 | M28: 0.92333333 | N28: 0.97222222 | O28: 1 | P28: 0.92703704 | Q28: =AVERAGE(H28,J28) -> 0.98333333 | R28: =AVERAGE(H28,J28,L28) -> 0.95555556 | S28: =AVERAGE(N28,O28,P28) -> 0.96641975
G29: Hellinger | H29: 0.96666667 | I29: 0.96666667 | J29: 0.96666667 | K29: 0.97777778 | L29: 0.9 | M29: 0.91111111 | N29: 0.97083333 | O29: 0.97777778 | P29: 0.92142857 | Q29: =AVERAGE(H29,J29) -> 0.96666667 | R29: =AVERAGE(H29,J29,L29) -> 0.94444444 | S29: =AVERAGE(N29,O29,P29) -> 0.95667989
D30: 8×8 | E30: 64 | F30: 18432 | G30: Chi-square | H30: 0.96666667 | I30: 0.96666667 | J30: 1 | K30: 1 | L30: 0.93333333 | M30: 0.94 | N30: 0.97083333 | O30: 1 | P30: 0.94555556 | Q30: =AVERAGE(H30,J30) -> 0.98333333 | R30: =AVERAGE(H30,J30,L30) -> 0.96666667 | S30: =AVERAGE(N30,O30,P30) -> 0.97212963
G31: Hellinger | H31: 0.96666667 | I31: 0.96666667 | J31: 1 | K31: 1 | L31: 0.93333333 | M31: 0.94166667 | N31: 0.97 | O31: 1 | P31: 0.94583333 | Q31: =AVERAGE(H31,J31) -> 0.98333333 | R31: =AVERAGE(H31,J31,L31) -> 0.96666667 | S31: =AVERAGE(N31,O31,P31) -> 0.97194444
C32: 12×8×8 | D32: 1×1 | E32: 1 | F32: 768 | G32: Chi-square | H32: 0.96666667 | I32: 0.97777778 | J32: 0.83333333 | K32: 0.88888889 | L32: 0.66666667 | M32: 0.74722222 | N32: 0.97777778 | O32: 0.89111111 | P32: 0.75632704 | Q32: =AVERAGE(H32,J32) -> 0.9 | R32: =AVERAGE(H32,J32,L32) -> 0.82222222 | S32: =AVERAGE(N32,O32,P32) -> 0.87507197
G33: Hellinger | H33: 1 | I33: 1 | J33: 0.83333333 | K33: 0.88055556 | L33: 0.66666667 | M33: 0.75777778 | N33: 1 | O33: 0.88293651 | P33: 0.76158923 | Q33: =AVERAGE(H33,J33) -> 0.91666667 | R33: =AVERAGE(H33,J33,L33) -> 0.83333333 | S33: =AVERAGE(N33,O33,P33) -> 0.88150858
D34: 2×2 | E34: 4 | F34: 3072 | G34: Chi-square | H34: 0.96666667 | I34: 0.97777778 | J34: 0.96666667 | K34: 0.96666667 | L34: 0.83333333 | M34: 0.87333333 | N34: 0.97777778 | O34: 0.97222222 | P34: 0.87704762 | Q34: =AVERAGE(H34,J34) -> 0.96666667 | R34: =AVERAGE(H34,J34,L34) -> 0.92222222 | S34: =AVERAGE(N34,O34,P34) -> 0.94234921
G35: Hellinger | H35: 0.96666667 | I35: 0.97777778 | J35: 0.96666667 | K35: 0.96666667 | L35: 0.86666667 | M35: 0.89166667 | N35: 0.97777778 | O35: 0.97222222 | P35: 0.89482527 | Q35: =AVERAGE(H35,J35) -> 0.96666667 | R35: =AVERAGE(H35,J35,L35) -> 0.93333333 | S35: =AVERAGE(N35,O35,P35) -> 0.94827509
D36: 3×3 | E36: 9 | F36: 6912 | G36: Chi-square | H36: 0.96666667 | I36: 0.96666667 | J36: 0.96666667 | K36: 0.96666667 | L36: 0.9 | M36: 0.9 | N36: 0.97222222 | O36: 0.97142857 | P36: 0.90867521 | Q36: =AVERAGE(H36,J36) -> 0.96666667 | R36: =AVERAGE(H36,J36,L36) -> 0.94444444 | S36: =AVERAGE(N36,O36,P36) -> 0.95077534
G37: Hellinger | H37: 0.96666667 | I37: 0.96666667 | J37: 0.96666667 | K37: 0.96666667 | L37: 0.9 | M37: 0.9 | N37: 0.97222222 | O37: 0.97222222 | P37: 0.90740741 | Q37: =AVERAGE(H37,J37) -> 0.96666667 | R37: =AVERAGE(H37,J37,L37) -> 0.94444444 | S37: =AVERAGE(N37,O37,P37) -> 0.95061728
D38: 4×4 | E38: 16 | F38: 12288 | G38: Chi-square | H38: 0.96666667 | I38: 0.97333333 | J38: 1 | K38: 1 | L38: 0.9 | M38: 0.9 | N38: 0.97333333 | O38: 1 | P38: 0.91365079 | Q38: =AVERAGE(H38,J38) -> 0.98333333 | R38: =AVERAGE(H38,J38,L38) -> 0.95555556 | S38: =AVERAGE(N38,O38,P38) -> 0.96232804
G39: Hellinger | H39: 0.96666667 | I39: 0.96666667 | J39: 1 | K39: 1 | L39: 0.9 | M39: 0.9 | N39: 0.97222222 | O39: 1 | P39: 0.91334776 | Q39: =AVERAGE(H39,J39) -> 0.98333333 | R39: =AVERAGE(H39,J39,L39) -> 0.95555556 | S39: =AVERAGE(N39,O39,P39) -> 0.96185666
D40: 5×5 | E40: 25 | F40: 19200 | G40: Chi-square | H40: 0.96666667 | I40: 0.96666667 | J40: 1 | K40: 1 | L40: 0.9 | M40: 0.90666667 | N40: 0.96969697 | O40: 1 | P40: 0.91619048 | Q40: =AVERAGE(H40,J40) -> 0.98333333 | R40: =AVERAGE(H40,J40,L40) -> 0.95555556 | S40: =AVERAGE(N40,O40,P40) -> 0.96196248
...

Sheet 4. Spatial pyramid
A1: Spatial pyramid representation (hierarchical 3D histograms): levels and level weights
A2: Notebook §3.5. Each level is a block histogram; levels are concatenated, each multiplied by its weight ('finer heavier' doubles the weight at every finer level, as in Lazebnik et al.). No inner margin.
A3: Color space | B3: Bins per channel | C3: Bin placement | D3: Levels | E3: Level weights | F3: Descriptor dim. | G3: Similarity | H3: map@1 QSD1 | I3: map@5 QSD1 | J3: map@1 QSD2 (GT crop) | K3: map@5 QSD2 (GT crop) | L3: map@1 + BG_Removal (T5) | M3: map@5 + BG_Removal (T5) | N3: MRR QSD1 | O3: MRR QSD2 (GT crop) | P3: MRR + BG_Removal (T5) | Q3: Mean map@1 (QSD1 + QSD2-GT) | R3: Mean map@1 (3 sets) | S3: Mean MRR (3 sets)
A4: HSV | B4: 4 (4×4×4) | C4: uniform | D4: 1×1 + 2×2 | E4: finer heavier 1:2 | F4: 320 | G4: Chi-square | H4: 0.93333333 | I4: 0.96111111 | J4: 0.9 | K4: 0.93333333 | L4: 0.66666667 | M4: 0.73333333 | N4: 0.96111111 | O4: 0.93888889 | P4: 0.74806878 | Q4: =AVERAGE(H4,J4) -> 0.91666667 | R4: =AVERAGE(H4,J4,L4) -> 0.83333333 | S4: =AVERAGE(N4,O4,P4) -> 0.88268959
G5: Hellinger | H5: 0.93333333 | I5: 0.96666667 | J5: 0.83333333 | K5: 0.9 | L5: 0.63333333 | M5: 0.71388889 | N5: 0.96666667 | O5: 0.90555556 | P5: 0.73389724 | Q5: =AVERAGE(H5,J5) -> 0.88333333 | R5: =AVERAGE(H5,J5,L5) -> 0.8 | S5: =AVERAGE(N5,O5,P5) -> 0.86870649
E6: uniform | F6: 320 | G6: Chi-square | H6: 0.93333333 | I6: 0.95555556 | J6: 0.86666667 | K6: 0.91666667 | L6: 0.6 | M6: 0.68611111 | N6: 0.95555556 | O6: 0.92083333 | P6: 0.69797115 | Q6: =AVERAGE(H6,J6) -> 0.9 | R6: =AVERAGE(H6,J6,L6) -> 0.8 | S6: =AVERAGE(N6,O6,P6) -> 0.85812001
G7: Hellinger | H7: 0.93333333 | I7: 0.96666667 | J7: 0.76666667 | K7: 0.85666667 | L7: 0.63333333 | M7: 0.7 | N7: 0.96666667 | O7: 0.86142857 | P7: 0.72318783 | Q7: =AVERAGE(H7,J7) -> 0.85 | R7: =AVERAGE(H7,J7,L7) -> 0.77777778 | S7: =AVERAGE(N7,O7,P7) -> 0.85042769
D8: 4×4 + 8×8 | E8: finer heavier 1:2 | F8: 5120 | G8: Chi-square | H8: 0.96666667 | I8: 0.96666667 | J8: 1 | K8: 1 | L8: 0.9 | M8: 0.90833333 | N8: 0.97222222 | O8: 1 | P8: 0.91865079 | Q8: =AVERAGE(H8,J8) -> 0.98333333 | R8: =AVERAGE(H8,J8,L8) -> 0.95555556 | S8: =AVERAGE(N8,O8,P8) -> 0.96362434
G9: Hellinger | H9: 0.96666667 | I9: 0.96666667 | J9: 1 | K9: 1 | L9: 0.86666667 | M9: 0.9 | N9: 0.97142857 | O9: 1 | P9: 0.90416667 | Q9: =AVERAGE(H9,J9) -> 0.98333333 | R9: =AVERAGE(H9,J9,L9) -> 0.94444444 | S9: =AVERAGE(N9,O9,P9) -> 0.95853175
E10: uniform | F10: 5120 | G10: Chi-square | H10: 0.96666667 | I10: 0.97333333 | J10: 1 | K10: 1 | L10: 0.9 | M10: 0.90666667 | N10: 0.97333333 | O10: 1 | P10: 0.91698413 | Q10: =AVERAGE(H10,J10) -> 0.98333333 | R10: =AVERAGE(H10,J10,L10) -> 0.95555556 | S10: =AVERAGE(N10,O10,P10) -> 0.96343915
G11: Hellinger | H11: 0.96666667 | I11: 0.96666667 | J11: 1 | K11: 1 | L11: 0.86666667 | M11: 0.9 | N11: 0.97222222 | O11: 1 | P11: 0.90416667 | Q11: =AVERAGE(H11,J11) -> 0.98333333 | R11: =AVERAGE(H11,J11,L11) -> 0.94444444 | S11: =AVERAGE(N11,O11,P11) -> 0.9587963
D12: 1×1 + 2×2 + 4×4 | E12: finer heavier 1:2:4 | F12: 1344 | G12: Chi-square | H12: 1 | I12: 1 | J12: 0.96666667 | K12: 0.97777778 | L12: 0.76666667 | M12: 0.81944444 | N12: 1 | O12: 0.97777778 | P12: 0.8325 | Q12: =AVERAGE(H12,J12) -> 0.98333333 | R12: =AVERAGE(H12,J12,L12) -> 0.91111111 | S12: =AVERAGE(N12,O12,P12) -> 0.93675926
G13: Hellinger | H13: 0.96666667 | I13: 0.98333333 | J13: 0.96666667 | K13: 0.975 | L13: 0.76666667 | M13: 0.82222222 | N13: 0.98333333 | O13: 0.975 | P13: 0.83611111 | Q13: =AVERAGE(H13,J13) -> 0.96666667 | R13: =AVERAGE(H13,J13,L13) -> 0.9 | S13: =AVERAGE(N13,O13,P13) -> 0.93148148
E14: uniform | F14: 1344 | G14: Chi-square | H14: 1 | I14: 1 | J14: 0.96666667 | K14: 0.975 | L14: 0.7 | M14: 0.78611111 | N14: 1 | O14: 0.975 | P14: 0.79583333 | Q14: =AVERAGE(H14,J14) -> 0.98333333 | R14: =AVERAGE(H14,J14,L14) -> 0.88888889 | S14: =AVERAGE(N14,O14,P14) -> 0.92361111
G15: Hellinger | H15: 1 | I15: 1 | J15: 0.96666667 | K15: 0.97333333 | L15: 0.7 | M15: 0.78611111 | N15: 1 | O15: 0.97333333 | P15: 0.79661172 | Q15: =AVERAGE(H15,J15) -> 0.98333333 | R15: =AVERAGE(H15,J15,L15) -> 0.88888889 | S15: =AVERAGE(N15,O15,P15) -> 0.92331502
D16: 1×1 + 3×3 + 5×5 | E16: finer heavier 1:2:4 | F16: 2240 | G16: Chi-square | H16: 0.96666667 | I16: 0.98333333 | J16: 0.96666667 | K16: 0.98333333 | L16: 0.76666667 | M16: 0.83611111 | N16: 0.98333333 | O16: 0.98333333 | P16: 0.84398148 | Q16: =AVERAGE(H16,J16) -> 0.96666667 | R16: =AVERAGE(H16,J16,L16) -> 0.9 | S16: =AVERAGE(N16,O16,P16) -> 0.93688272
G17: Hellinger | H17: 0.96666667 | I17: 0.98333333 | J17: 1 | K17: 1 | L17: 0.76666667 | M17: 0.84111111 | N17: 0.98333333 | O17: 1 | P17: 0.84527778 | Q17: =AVERAGE(H17,J17) -> 0.98333333 | R17: =AVERAGE(H17,J17,L17) -> 0.91111111 | S17: =AVERAGE(N17,O17,P17) -> 0.94287037
E18: uniform | F18: 2240 | G18: Chi-square | H18: 1 | I18: 1 | J18: 0.96666667 | K18: 0.98333333 | L18: 0.73333333 | M18: 0.80555556 | N18: 1 | O18: 0.98333333 | P18: 0.81608586 | Q18: =AVERAGE(H18,J18) -> 0.98333333 | R18: =AVERAGE(H18,J18,L18) -> 0.9 | S18: =AVERAGE(N18,O18,P18) -> 0.93313973
G19: Hellinger | H19: 0.96666667 | I19: 0.98333333 | J19: 0.96666667 | K19: 0.97777778 | L19: 0.76666667 | M19: 0.81944444 | N19: 0.98333333 | O19: 0.97777778 | P19: 0.83174603 | Q19: =AVERAGE(H19,J19) -> 0.96666667 | R19: =AVERAGE(H19,J19,L19) -> 0.9 | S19: =AVERAGE(N19,O19,P19) -> 0.93095238
D20: 2×2 + 4×4 + 6×6 | E20: finer heavier 1:2:4 | F20: 3584 | G20: Chi-square | H20: 0.96666667 | I20: 0.97333333 | J20: 1 | K20: 1 | L20: 0.83333333 | M20: 0.87777778 | N20: 0.97333333 | O20: 1 | P20: 0.88670635 | Q20: =AVERAGE(H20,J20) -> 0.98333333 | R20: =AVERAGE(H20,J20,L20) -> 0.93333333 | S20: =AVERAGE(N20,O20,P20) -> 0.95334656
G21: Hellinger | H21: 0.96666667 | I21: 0.97333333 | J21: 1 | K21: 1 | L21: 0.83333333 | M21: 0.88166667 | N21: 0.97333333 | O21: 1 | P21: 0.88537037 | Q21: =AVERAGE(H21,J21) -> 0.98333333 | R21: =AVERAGE(H21,J21,L21) -> 0.93333333 | S21: =AVERAGE(N21,O21,P21) -> 0.95290123
E22: uniform | F22: 3584 | G22: Chi-square | H22: 0.96666667 | I22: 0.97777778 | J22: 0.96666667 | K22: 0.98333333 | L22: 0.76666667 | M22: 0.83888889 | N22: 0.97777778 | O22: 0.98333333 | P22: 0.84698413 | Q22: =AVERAGE(H22,J22) -> 0.96666667 | R22: =AVERAGE(H22,J22,L22) -> 0.9 | S22: =AVERAGE(N22,O22,P22) -> 0.93603175
G23: Hellinger | H23: 0.96666667 | I23: 0.98333333 | J23: 1 | K23: 1 | L23: 0.8 | M23: 0.85944444 | N23: 0.98333333 | O23: 1 | P23: 0.86277778 | Q23: =AVERAGE(H23,J23) -> 0.98333333 | R23: =AVERAGE(H23,J23,L23) -> 0.92222222 | S23: =AVERAGE(N23,O23,P23) -> 0.9487037
D24: 1×1 + 2×2 + 4×4 + 8×8 | E24: finer heavier 1:2:4:8 | F24: 5440 | G24: Chi-square | H24: 0.96666667 | I24: 0.975 | J24: 1 | K24: 1 | L24: 0.86666667 | M24: 0.89166667 | N24: 0.975 | O24: 1 | P24: 0.90138889 | Q24: =AVERAGE(H24,J24) -> 0.98333333 | R24: =AVERAGE(H24,J24,L24) -> 0.94444444 | S24: =AVERAGE(N24,O24,P24) -> 0.9587963
G25: Hellinger | H25: 0.96666667 | I25: 0.97333333 | J25: 1 | K25: 1 | L25: 0.86666667 | M25: 0.89444444 | N25: 0.97333333 | O25: 1 | P25: 0.89814815 | Q25: =AVERAGE(H25,J25) -> 0.98333333 | R25: =AVERAGE(H25,J25,L25) -> 0.94444444 | S25: =AVERAGE(N25,O25,P25) -> 0.95716049
E26: uniform | F26: 5440 | G26: Chi-square | H26: 1 | I26: 1 | J26: 0.96666667 | K26: 0.98333333 | L26: 0.8 | M26: 0.83888889 | N26: 1 | O26: 0.98333333 | P26: 0.85164141 | Q26: =AVERAGE(H26,J26) -> 0.98333333 | R26: =AVERAGE(H26,J26,L26) -> 0.92222222 | S26: =AVERAGE(N26,O26,P26) -> 0.94499158
G27: Hellinger | H27: 0.96666667 | I27: 0.98333333 | J27: 1 | K27: 1 | L27: 0.76666667 | M27: 0.82611111 | N27: 0.98333333 | O27: 1 | P27: 0.83444444 | Q27: =AVERAGE(H27,J27) -> 0.98333333 | R27: =AVERAGE(H27,J27,L27) -> 0.91111111 | S27: =AVERAGE(N27,O27,P27) -> 0.93925926
B28: 8×6×6 | C28: uniform | D28: 1×1 + 2×2 | E28: finer heavier 1:2 | F28: 1440 | G28: Chi-square | H28: 0.96666667 | I28: 0.98333333 | J28: 0.9 | K28: 0.93333333 | L28: 0.8 | M28: 0.84111111 | N28: 0.98333333 | O28: 0.93888889 | P28: 0.84614815 | Q28: =AVERAGE(H28,J28) -> 0.93333333 | R28: =AVERAGE(H28,J28,L28) -> 0.88888889 | S28: =AVERAGE(N28,O28,P28) -> 0.92279012
G29: Hellinger | H29: 0.96666667 | I29: 0.98333333 | J29: 0.9 | K29: 0.93333333 | L29: 0.83333333 | M29: 0.85777778 | N29: 0.98333333 | O29: 0.9375 | P29: 0.86195751 | Q29: =AVERAGE(H29,J29) -> 0.93333333 | R29: =AVERAGE(H29,J29,L29) -> 0.9 | S29: =AVERAGE(N29,O29,P29) -> 0.92759695
E30: uniform | F30: 1440 | G30: Chi-square | H30: 0.96666667 | I30: 0.98333333 | J30: 0.9 | K30: 0.93333333 | L30: 0.76666667 | M30: 0.81333333 | N30: 0.98333333 | O30: 0.93703704 | P30: 0.8231746 | Q30: =AVERAGE(H30,J30) -> 0.93333333 | R30: =AVERAGE(H30,J30,L30) -> 0.87777778 | S30: =AVERAGE(N30,O30,P30) -> 0.91451499
G31: Hellinger | H31: 1 | I31: 1 | J31: 0.9 | K31: 0.93333333 | L31: 0.83333333 | M31: 0.855 | N31: 1 | O31: 0.9375 | P31: 0.858885 | Q31: =AVERAGE(H31,J31) -> 0.95 | R31: =AVERAGE(H31,J31,L31) -> 0.91111111 | S31: =AVERAGE(N31,O31,P31) -> 0.93212833
D32: 4×4 + 8×8 | E32: finer heavier 1:2 | F32: 23040 | G32: Chi-square | H32: 0.96666667 | I32: 0.96666667 | J32: 1 | K32: 1 | L32: 0.93333333 | M32: 0.93333333 | N32: 0.97222222 | O32: 1 | P32: 0.94444444 | Q32: =AVERAGE(H32,J32) -> 0.98333333 | R32: =AVERAGE(H32,J32,L32) -> 0.96666667 | S32: =AVERAGE(N32,O32,P32) -> 0.97222222
G33: Hellinger | H33: 0.96666667 | I33: 0.96666667 | J33: 1 | K33: 1 | L33: 0.9 | M33: 0.925 | N33: 0.97083333 | O33: 1 | P33: 0.9297619 | Q33: =AVERAGE(H33,J33) -> 0.98333333 | R33: =AVERAGE(H33,J33,L33) -> 0.95555556 | S33: =AVERAGE(N33,O33,P33) -> 0.96686508
E34: uniform | F34: 23040 | G34: Chi-square | H34: 0.96666667 | I34: 0.96666667 | J34: 1 | K34: 1 | L34: 0.9 | M34: 0.91666667 | N34: 0.97222222 | O34: 1 | P34: 0.92777778 | Q34: =AVERAGE(H34,J34) -> 0.98333333 | R34: =AVERAGE(H34,J34,L34) -> 0.95555556 | S34: =AVERAGE(N34,O34,P34) -> 0.96666667
G35: Hellinger | H35: 0.96666667 | I35: 0.96666667 | J35: 1 | K35: 1 | L35: 0.9 | M35: 0.925 | N35: 0.97142857 | O35: 1 | P35: 0.9297619 | Q35: =AVERAGE(H35,J35) -> 0.98333333 | R35: =AVERAGE(H35,J35,L35) -> 0.95555556 | S35: =AVERAGE(N35,O35,P35) -> 0.96706349
D36: 1×1 + 2×2 + 4×4 | E36: finer heavier 1:2:4 | F36: 6048 | G36: Chi-square | H36: 0.96666667 | I36: 0.975 | J36: 0.96666667 | K36: 0.97777778 | L36: 0.83333333 | M36: 0.87333333 | N36: 0.975 | O36: 0.97777778 | P36: 0.88222222 | Q36: =AVERAGE(H36,J36) -> 0.96666667 | R36: =AVERAGE(H36,J36,L36) -> 0.92222222 | S36: =AVERAGE(N36,O36,P36) -> 0.945
G37: Hellinger | H37: 0.96666667 | I37: 0.975 | J37: 0.96666667 | K37: 0.97777778 | L37: 0.83333333 | M37: 0.875 | N37: 0.975 | O37: 0.97777778 | P37: 0.88194444 | Q37: =AVERAGE(H37,J37) -> 0.96666667 | R37: =AVERAGE(H37,J37,L37) -> 0.92222222 | S37: =AVERAGE(N37,O37,P37) -> 0.94490741
E38: uniform | F38: 6048 | G38: Chi-square | H38: 0.96666667 | I38: 0.98333333 | J38: 0.93333333 | K38: 0.95666667 | L38: 0.83333333 | M38: 0.86777778 | N38: 0.98333333 | O38: 0.95666667 | P38: 0.8747619 | Q38: =AVERAGE(H38,J38) -> 0.95 | R38: =AVERAGE(H38,J38,L38) -> 0.91111111 | S38: =AVERAGE(N38,O38,P38) -> 0.93825397
G39: Hellinger | H39: 0.96666667 | I39: 0.97777778 | J39: 0.93333333 | K39: 0.95666667 | L39: 0.83333333 | M39: 0.87333333 | N39: 0.97777778 | O39: 0.95666667 | P39: 0.87899782 | Q39: =AVERAGE(H39,J39) -> 0.95 | R39: =AVERAGE(H39,J39,L39) -> 0.91111111 | S39: =AVERAGE(N39,O39,P39) -> 0.93781409
D40: 1×1 + 3×3 + 5×5 | E40: finer heavier 1:2:4 | F40: 10080 | G40: Chi-square | H40: 0.96666667 | I40: 0.975 | J40: 0.96666667 | K40: 0.975 | L40: 0.83333333 | M40: 0.86666667 | N40: 0.975 | O40: 0.975 | P40: 0.88174603 | Q40: =AVERAGE(H40,J40) -> 0.96666667 | R40: =AVERAGE(H40,J40,L40) -> 0.92222222 | S40: =AVERAGE(N40,O40,P40) -> 0.94391534
...

Sheet 5. Distances
A1: Similarity / distance measures on the best block descriptors
A2: Notebook §3.6. With normalised histograms, histogram intersection ranks exactly like L1.
A3: Descriptor | B3: Similarity | C3: map@1 QSD1 | D3: map@5 QSD1 | E3: map@1 QSD2 (GT crop) | F3: map@5 QSD2 (GT crop) | G3: map@1 + BG_Removal (T5) | H3: map@5 + BG_Removal (T5) | I3: MRR QSD1 | J3: MRR QSD2 (GT crop) | K3: MRR + BG_Removal (T5) | L3: Mean map@1 (QSD1 + QSD2-GT) | M3: Mean map@1 (3 sets) | N3: Mean MRR (3 sets)
A4: HSV 3D 4 (4×4×4), 5×5 blocks (uniform bins) | B4: L1 (= intersection) | C4: 0.96666667 | D4: 0.97777778 | E4: 1 | F4: 1 | G4: 0.86666667 | H4: 0.89166667 | I4: 0.97777778 | J4: 1 | K4: 0.89953704 | L4: =AVERAGE(C4,E4) -> 0.98333333 | M4: =AVERAGE(C4,E4,G4) -> 0.94444444 | N4: =AVERAGE(I4,J4,K4) -> 0.95910494
B5: Euclidean | C5: 0.9 | D5: 0.925 | E5: 0.76666667 | F5: 0.81388889 | G5: 0.66666667 | H5: 0.68333333 | I5: 0.92595238 | J5: 0.81628061 | K5: 0.69978171 | L5: =AVERAGE(C5,E5) -> 0.83333333 | M5: =AVERAGE(C5,E5,G5) -> 0.77777778 | N5: =AVERAGE(I5,J5,K5) -> 0.8140049
B6: Chi-square | C6: 0.96666667 | D6: 0.975 | E6: 1 | F6: 1 | G6: 0.86666667 | H6: 0.88444444 | I6: 0.975 | J6: 1 | K6: 0.89396825 | L6: =AVERAGE(C6,E6) -> 0.98333333 | M6: =AVERAGE(C6,E6,G6) -> 0.94444444 | N6: =AVERAGE(I6,J6,K6) -> 0.95632275
B7: Hellinger | C7: 0.96666667 | D7: 0.97333333 | E7: 1 | F7: 1 | G7: 0.83333333 | H7: 0.87888889 | I7: 0.97333333 | J7: 1 | K7: 0.88259259 | L7: =AVERAGE(C7,E7) -> 0.98333333 | M7: =AVERAGE(C7,E7,G7) -> 0.93333333 | N7: =AVERAGE(I7,J7,K7) -> 0.95197531
B8: Jensen-Shannon | C8: 0.96666667 | D8: 0.975 | E8: 1 | F8: 1 | G8: 0.86666667 | H8: 0.88444444 | I8: 0.975 | J8: 1 | K8: 0.89396825 | L8: =AVERAGE(C8,E8) -> 0.98333333 | M8: =AVERAGE(C8,E8,G8) -> 0.94444444 | N8: =AVERAGE(I8,J8,K8) -> 0.95632275
A9: HSV 3D 8×6×6, 5×5 blocks (uniform bins) | B9: L1 (= intersection) | C9: 0.96666667 | D9: 0.975 | E9: 1 | F9: 1 | G9: 0.9 | H9: 0.92333333 | I9: 0.975 | J9: 1 | K9: 0.92888889 | L9: =AVERAGE(C9,E9) -> 0.98333333 | M9: =AVERAGE(C9,E9,G9) -> 0.95555556 | N9: =AVERAGE(I9,J9,K9) -> 0.96796296
B10: Euclidean | C10: 0.83333333 | D10: 0.84444444 | E10: 0.76666667 | F10: 0.78888889 | G10: 0.6 | H10: 0.62777778 | I10: 0.85491522 | J10: 0.79603829 | K10: 0.64485907 | L10: =AVERAGE(C10,E10) -> 0.8 | M10: =AVERAGE(C10,E10,G10) -> 0.73333333 | N10: =AVERAGE(I10,J10,K10) -> 0.76527086
B11: Chi-square | C11: 0.96666667 | D11: 0.96666667 | E11: 1 | F11: 1 | G11: 0.86666667 | H11: 0.90666667 | I11: 0.97222222 | J11: 1 | K11: 0.91222222 | L11: =AVERAGE(C11,E11) -> 0.98333333 | M11: =AVERAGE(C11,E11,G11) -> 0.94444444 | N11: =AVERAGE(I11,J11,K11) -> 0.96148148
B12: Hellinger | C12: 0.96666667 | D12: 0.96666667 | E12: 0.96666667 | F12: 0.97777778 | G12: 0.93333333 | H12: 0.94166667 | I12: 0.97083333 | J12: 0.97777778 | K12: 0.94642857 | L12: =AVERAGE(C12,E12) -> 0.96666667 | M12: =AVERAGE(C12,E12,G12) -> 0.95555556 | N12: =AVERAGE(I12,J12,K12) -> 0.96501323
B13: Jensen-Shannon | C13: 0.96666667 | D13: 0.96666667 | E13: 0.96666667 | F13: 0.98333333 | G13: 0.93333333 | H13: 0.94166667 | I13: 0.97222222 | J13: 0.98333333 | K13: 0.94642857 | L13: =AVERAGE(C13,E13) -> 0.96666667 | M13: =AVERAGE(C13,E13,G13) -> 0.95555556 | N13: =AVERAGE(I13,J13,K13) -> 0.96732804
A14: HSV 3D 12×8×8, 4×4 blocks (uniform bins) | B14: L1 (= intersection) | C14: 0.96666667 | D14: 0.975 | E14: 0.96666667 | F14: 0.98333333 | G14: 0.9 | H14: 0.9 | I14: 0.975 | J14: 0.98333333 | K14: 0.91448413 | L14: =AVERAGE(C14,E14) -> 0.96666667 | M14: =AVERAGE(C14,E14,G14) -> 0.94444444 | N14: =AVERAGE(I14,J14,K14) -> 0.95760582
B15: Euclidean | C15: 0.7 | D15: 0.73333333 | E15: 0.66666667 | F15: 0.68333333 | G15: 0.6 | H15: 0.61666667 | I15: 0.74730427 | J15: 0.69280285 | K15: 0.62372249 | L15: =AVERAGE(C15,E15) -> 0.68333333 | M15: =AVERAGE(C15,E15,G15) -> 0.65555556 | N15: =AVERAGE(I15,J15,K15) -> 0.6879432
B16: Chi-square | C16: 0.96666667 | D16: 0.97333333 | E16: 1 | F16: 1 | G16: 0.9 | H16: 0.9 | I16: 0.97333333 | J16: 1 | K16: 0.91365079 | L16: =AVERAGE(C16,E16) -> 0.98333333 | M16: =AVERAGE(C16,E16,G16) -> 0.95555556 | N16: =AVERAGE(I16,J16,K16) -> 0.96232804
B17: Hellinger | C17: 0.96666667 | D17: 0.96666667 | E17: 1 | F17: 1 | G17: 0.9 | H17: 0.9 | I17: 0.97222222 | J17: 1 | K17: 0.91334776 | L17: =AVERAGE(C17,E17) -> 0.98333333 | M17: =AVERAGE(C17,E17,G17) -> 0.95555556 | N17: =AVERAGE(I17,J17,K17) -> 0.96185666
B18: Jensen-Shannon | C18: 0.96666667 | D18: 0.96666667 | E18: 1 | F18: 1 | G18: 0.9 | H18: 0.9 | I18: 0.97222222 | J18: 1 | K18: 0.91334776 | L18: =AVERAGE(C18,E18) -> 0.98333333 | M18: =AVERAGE(C18,E18,G18) -> 0.95555556 | N18: =AVERAGE(I18,J18,K18) -> 0.96185666
A19: Lab 3D 8×16×16, 6×6 blocks (range-adapted bins) | B19: L1 (= intersection) | C19: 0.96666667 | D19: 0.96666667 | E19: 0.96666667 | F19: 0.98333333 | G19: 0.9 | H19: 0.9 | I19: 0.97037037 | J19: 0.98333333 | K19: 0.91285714 | L19: =AVERAGE(C19,E19) -> 0.96666667 | M19: =AVERAGE(C19,E19,G19) -> 0.94444444 | N19: =AVERAGE(I19,J19,K19) -> 0.95552028
B20: Euclidean | C20: 0.7 | D20: 0.74 | E20: 0.76666667 | F20: 0.78333333 | G20: 0.63333333 | H20: 0.63333333 | I20: 0.74728102 | J20: 0.79057224 | K20: 0.65216981 | L20: =AVERAGE(C20,E20) -> 0.73333333 | M20: =AVERAGE(C20,E20,G20) -> 0.7 | N20: =AVERAGE(I20,J20,K20) -> 0.73000769
B21: Chi-square | C21: 0.96666667 | D21: 0.96666667 | E21: 0.93333333 | F21: 0.96666667 | G21: 0.9 | H21: 0.9 | I21: 0.97037037 | J21: 0.96666667 | K21: 0.91179894 | L21: =AVERAGE(C21,E21) -> 0.95 | M21: =AVERAGE(C21,E21,G21) -> 0.93333333 | N21: =AVERAGE(I21,J21,K21) -> 0.94961199
B22: Hellinger | C22: 0.96666667 | D22: 0.96666667 | E22: 0.96666667 | F22: 0.98333333 | G22: 0.9 | H22: 0.90666667 | I22: 0.97 | J22: 0.98333333 | K22: 0.9130303 | L22: =AVERAGE(C22,E22) -> 0.96666667 | M22: =AVERAGE(C22,E22,G22) -> 0.94444444 | N22: =AVERAGE(I22,J22,K22) -> 0.95545455
B23: Jensen-Shannon | C23: 0.96666667 | D23: 0.96666667 | E23: 0.96666667 | F23: 0.98333333 | G23: 0.9 | H23: 0.9 | I23: 0.97 | J23: 0.98333333 | K23: 0.91222222 | L23: =AVERAGE(C23,E23) -> 0.96666667 | M23: =AVERAGE(C23,E23,G23) -> 0.94444444 | N23: =AVERAGE(I23,J23,K23) -> 0.95518519
A24: YCrCb 3D 6×12×12, 3×3 blocks (range-adapted bins) | B24: L1 (= intersection) | C24: 0.96666667 | D24: 0.96666667 | E24: 0.93333333 | F24: 0.96666667 | G24: 0.86666667 | H24: 0.89 | I24: 0.97222222 | J24: 0.96666667 | K24: 0.89529954 | L24: =AVERAGE(C24,E24) -> 0.95 | M24: =AVERAGE(C24,E24,G24) -> 0.92222222 | N24: =AVERAGE(I24,J24,K24) -> 0.94472948
B25: Euclidean | C25: 0.83333333 | D25: 0.87777778 | E25: 0.8 | F25: 0.80833333 | G25: 0.7 | H25: 0.73166667 | I25: 0.88088833 | J25: 0.81777519 | K25: 0.74315495 | L25: =AVERAGE(C25,E25) -> 0.81666667 | M25: =AVERAGE(C25,E25,G25) -> 0.77777778 | N25: =AVERAGE(I25,J25,K25) -> 0.81393949
B26: Chi-square | C26: 0.96666667 | D26: 0.96666667 | E26: 1 | F26: 1 | G26: 0.83333333 | H26: 0.86666667 | I26: 0.97083333 | J26: 1 | K26: 0.87617284 | L26: =AVERAGE(C26,E26) -> 0.98333333 | M26: =AVERAGE(C26,E26,G26) -> 0.93333333 | N26: =AVERAGE(I26,J26,K26) -> 0.94900206
B27: Hellinger | C27: 0.96666667 | D27: 0.96666667 | E27: 1 | F27: 1 | G27: 0.86666667 | H27: 0.89444444 | I27: 0.97037037 | J27: 1 | K27: 0.89826389 | L27: =AVERAGE(C27,E27) -> 0.98333333 | M27: =AVERAGE(C27,E27,G27) -> 0.94444444 | N27: =AVERAGE(I27,J27,K27) -> 0.95621142
B28: Jensen-Shannon | C28: 0.96666667 | D28: 0.96666667 | E28: 1 | F28: 1 | G28: 0.86666667 | H28: 0.89 | I28: 0.97083333 | J28: 1 | K28: 0.89351852 | L28: =AVERAGE(C28,E28) -> 0.98333333 | M28: =AVERAGE(C28,E28,G28) -> 0.94444444 | N28: =AVERAGE(I28,J28,K28) -> 0.95478395
A29: YCrCb 3D 6×12×12, 6×6 blocks (range-adapted bins) | B29: L1 (= intersection) | C29: 0.96666667 | D29: 0.96666667 | E29: 0.96666667 | F29: 0.98333333 | G29: 0.86666667 | H29: 0.9 | I29: 0.96969697 | J29: 0.98333333 | K29: 0.90544872 | L29: =AVERAGE(C29,E29) -> 0.96666667 | M29: =AVERAGE(C29,E29,G29) -> 0.93333333 | N29: =AVERAGE(I29,J29,K29) -> 0.95282634
B30: Euclidean | C30: 0.9 | D30: 0.90666667 | E30: 0.8 | F30: 0.81666667 | G30: 0.7 | H30: 0.72222222 | I30: 0.90833333 | J30: 0.82423266 | K30: 0.73283871 | L30: =AVERAGE(C30,E30) -> 0.85 | M30: =AVERAGE(C30,E30,G30) -> 0.8 | N30: =AVERAGE(I30,J30,K30) -> 0.82180157
B31: Chi-square | C31: 0.96666667 | D31: 0.96666667 | E31: 0.96666667 | F31: 0.98333333 | G31: 0.9 | H31: 0.91666667 | I31: 0.96923077 | J31: 0.98333333 | K31: 0.9217037 | L31: =AVERAGE(C31,E31) -> 0.96666667 | M31: =AVERAGE(C31,E31,G31) -> 0.94444444 | N31: =AVERAGE(I31,J31,K31) -> 0.95808927
B32: Hellinger | C32: 0.96666667 | D32: 0.96666667 | E32: 0.96666667 | F32: 0.98333333 | G32: 0.9 | H32: 0.91666667 | I32: 0.96904762 | J32: 0.98333333 | K32: 0.92121212 | L32: =AVERAGE(C32,E32) -> 0.96666667 | M32: =AVERAGE(C32,E32,G32) -> 0.94444444 | N32: =AVERAGE(I32,J32,K32) -> 0.95786436
B33: Jensen-Shannon | C33: 0.96666667 | D33: 0.96666667 | E33: 0.96666667 | F33: 0.98333333 | G33: 0.9 | H33: 0.91666667 | I33: 0.96923077 | J33: 0.98333333 | K33: 0.9210303 | L33: =AVERAGE(C33,E33) -> 0.96666667 | M33: =AVERAGE(C33,E33,G33) -> 0.94444444 | N33: =AVERAGE(I33,J33,K33) -> 0.9578648

Sheet 6. Margin + BG removal (T5)
A1: Task 5: robustness to imperfect masks – inner margin removed on each side (queries and BBDD)
A2: Notebook §6 / §6.1. map@1 + BG_Removal (T5) = QSD2 cropped with OUR masks (method M2). The final methods use a 5% margin and Hellinger.
A3: Descriptor | B3: Inner margin | C3: Similarity | D3: map@1 QSD1 | E3: map@5 QSD1 | F3: map@1 QSD2 (GT crop) | G3: map@5 QSD2 (GT crop) | H3: map@1 + BG_Removal (T5) | I3: map@5 + BG_Removal (T5) | J3: MRR QSD1 | K3: MRR QSD2 (GT crop) | L3: MRR + BG_Removal (T5) | M3: Mean map@1 (QSD1 + QSD2-GT) | N3: Mean map@1 (3 sets) | O3: Mean MRR (3 sets)
A4: HSV 3D 12×8×8 (uniform), 4×4 blocks | B4: 0% | C4: Chi-square | D4: 0.96666667 | E4: 0.97333333 | F4: 1 | G4: 1 | H4: 0.9 | I4: 0.9 | J4: 0.97333333 | K4: 1 | L4: 0.91365079 | M4: =AVERAGE(D4,F4) -> 0.98333333 | N4: =AVERAGE(D4,F4,H4) -> 0.95555556 | O4: =AVERAGE(J4,K4,L4) -> 0.96232804
